Workbook

Sheet Data Dictionary
A1: This data dictionary is to assist you in filling out/interpreting the fields on the tagging metadata data sheet. It need not be submitted with your data.
A2: All dates and times are to be recorded in UTC 24-hour format. All latitudes and longitudes should reference the WGS84 map datum. For help with this form, please contact the OTN Data Centre: otndc@Dal.Ca or 1-902-494-8470.
A4: Field Name | B4: Units/format example | C4: Definition
A5: ANIMAL_ID (floy tag ID, pit tag code, etc.) | B5: format: free text, not otherwise specified | C5: Identification code that uniquely identifies each animal, as specified by the researcher. This can be a floy tag ID, pit tag ID, or other unique identifier.
A6: TAG_TYPE | B6: as in: acoustic | C6: Type of tag attached to animal. Some possible options are: acoustic tag, satellite tag, PIT tag, ID tag, brand, business card tag.
A7: TAG_MANUFACTURER | B7: as in: VEMCO | C7: Name of tag manufacturer.
A8: TAG_MODEL | B8: as in: V9-6L | C8: Tag model number as provided by the manufacturer.
A9: TAG_SERIAL_NUMBER | B9: as in: 1036912 | C9: Serial number assigned by tag manufacturer to uniquely identify tag.
A10: TAG_ID_CODE | B10: as in: 1450 | C10: In the case of an acoustic tag or Vemco mobile transceiver, this is the identification code transmitted by the tag, which is available from the tag manufacturer. For a satellite tag, it is the PTT code. For a VHF tag, this is the frequency at which the tag transmits.
A11: TAG_CODE_SPACE | B11: as in: A69-1303 | C11: Code space as provided by the tag manufacturer.
A12: TAG_IMPLANT_TYPE | B12: as in: internal | C12: Indicates how tag was attached to animal (e.g. internal, external, oral, gastric, subcutaneous, etc.).
A13: TAG_IMPLANT_METHOD | B13: as in: inserted into abdominal cavity through midventral line incision, closed using 2 polydioxanone monofilament sutures. | C13: Describe method and materials used to attach tag to animal.
A14: TAG_ACTIVATION_DATE | B14: as in: 2007-04-23; format: yyyy-mm-dd | C14: Date tag activated, in UTC.
A15: EST_TAG_LIFE | B15: as in: 90 days | C15: Estimate of the duration of time during which the tag will be transmitting. For tags that are recovered, this is the number of days between release and recapture.
... A35: DNA_SAMPLE_TAKEN | B35: as in: yes | C35: Yes/no, if the animal that carries the acoustic tag is also sampled for DNA.
A36: TREATMENT_TYPE | C36: Contains a designation of treatment group as appropriate for the particular study. Researchers will have to contact the authors directly for definitions. Try to make these as clear as possible (e.g. use Control instead of C, Lake release instead of Lake).
A37: RELEASE_GROUP | B37: as in: 1 | C37: Numerical field that increments sequentially for each release date.
A38: RELEASE_LOCATION | B38: as in: Keogh River, Winter Harbor, St. Paul's Island, or Boutilier's Point | C38: Name of release location. Please refer to a specific nearby point of land, town, island, or body of water that uniquely identifies this tagging location. For example, Gulf of Maine is too broad a region, but Winter Harbor would be appropriate.
A39: RELEASE_LATITUDE | B39: as in: 43.12345; format: dd.ddddd; places: to 5 decimals | C39: Latitude of release location. Note: in the southern hemisphere all latitudes must be negative.
A40: RELEASE_LONGITUDE | B40: as in: -123.12345; format: ddd.ddddd; places: to 5 decimals | C40: Longitude of release location. Note: in the western hemisphere all longitudes must be negative.
A41: UTC_RELEASE_DATE_TIME | B41: as in: 2009-05-17T14:12:00; format: yyyy-mm-ddThh:mm:ss | C41: Date and time that tagged animal was released, in UTC.
A42: HARVEST_DATE | B42: as in: 2009-05-17; format: yyyy-mm-ddThh:mm:ss | C42: Date that the tag was recovered from a captured animal, in UTC. example: if a fish is caught and the tag returned to the researcher. Note this is the date the previously released animal was recaptured. It will affect the enddate of the previous release as well as the estimated tag life for this release.
A43: CAPTURE_DEPTH | B43: as in: 200 | C43: Water depth where the fish were caught, in metres.
A44: TEMPERATURE_CHANGE | B44: as in: 20.0; places: to 1 decimal | C44: Difference between the water temperature at the depth at which the fish were caught and the surface water temperature, in degrees celsius.
A45: HOLDING_TEMPERATURE | B45: as in: 10.3; places: to 1 decimal | C45: This measure is the highest or lowest water bath temperature the fish will experience during holding (depends if surgical water temperatures are increasing or decreasing relative to initial water temperature reading). For example, if tagging is being conducted in early summer, the recirculating bath is 10.2 degrees, and the sedation bath is 10.0 degrees, then the higher value would be recorded to one decimal place ( i.e. 10.2°C).
A46: PREOP_HOLDING_PERIOD | B46: as in: 2 hours | C46: Time that animal is held prior to surgery, in hours.
A47: POST_OP_HOLDING_PERIOD | B47: as in: 48 hours | C47: Time the animal is held after surgery until release, in hours.
A48: SURGERY_LOCATION | B48: as in: Keogh River fence | C48: Short name of surgery location (i.e. hatchery name).
... A61: COMMENTS | B61: as in: fish was exposed to aluminum during surgical procedure | C61: Any comments deemed to have scientific relevance by the tagger.

Sheet Tag Metadata
A1: ANIMAL_ID (floy tag ID, pit tag code, etc.) | B1: TAG_TYPE | C1: TAG_MANUFACTURER | D1: TAG_MODEL | E1: TAG_SERIAL_NUMBER | F1: TAG_ID_CODE | G1: TAG_CODE_SPACE | H1: TAG_IMPLANT_TYPE | I1: TAG_IMPLANT_METHOD | J1: TAG_ACTIVATION_DATE | K1: EST_TAG_LIFE | L1: TAGGER | M1: TAG_OWNER_PI | N1: TAG_OWNER_ORGANIZATION | O1: COMMON_NAME_E | P1: SCIENTIFIC_NAME | Q1: CAPTURE_LOCATION | R1: CAPTURE_LATITUDE | S1: CAPTURE_LONGITUDE | T1: WILD_OR_HATCHERY | U1: STOCK | V1: LENGTH (m) | W1: WEIGHT (kg) | X1: LENGTH_TYPE | Y1: LENGTH2 (m) | Z1: LENGTH2_TYPE | AA1: LIFE_STAGE | AB1: AGE | AC1: AGE_UNITS | AD1: SEX | AE1: DNA_SAMPLE_TAKEN | AF1: TREATMENT_TYPE | AG1: RELEASE_GROUP | AH1: RELEASE_LOCATION | AI1: RELEASE_LATITUDE | AJ1: RELEASE_LONGITUDE | AK1: UTC_RELEASE_DATE_TIME | AL1: HARVEST_DATE | AM1: CAPTURE_DEPTH (m) | AN1: TEMPERATURE_CHANGE (degrees C) | AO1: HOLDING_TEMPERATURE (degrees C) | AP1: PREOP_HOLD_PERIOD | AQ1: POSTOP_HOLD_PERIOD | AR1: SURGERY_LOCATION | AS1: DATE_OF_SURGERY | AT1: SURGERY_LATITUDE | AU1: SURGERY_LONGITUDE | AV1: SEDATIVE | AW1: SEDATIVE_CONCENTRATION (ppm) | AX1: ANAESTHETIC | AY1: BUFFER | AZ1: ANAESTHETIC_CONCENTRATION (ppm) | BA1: BUFFER_CONCENTRATION_IN_ANAESTHETIC (ppm) | BB1: ANAESTHETIC_CONCENTRATION_IN_RECIRCULATION (ppm) | BC1: BUFFER_CONCENTRATION_IN_RECIRCULATION (ppm) | BD1: DISSOLVED_OXYGEN (ppm) | BE1: COMMENTS
A2: 3D9.257C661983 | B2: Acoustic | C2: VEMCO | D2: V16-4x | E2: 1194443 | F2: 24577 | G2: A69-9001 | H2: INTERNAL | I2: Midventral line incision, sutures | J2: 42194 | K2: 2435 days | L2: Catherine Johnston/Kevin Lachapelle | M2: Gayle Zydlewski | N2: Universtiy of Maine | O2: Shortnose Sturgeon | P2: Acipenser brevirostrum | Q2: Penobscot River | R2: 44.68104 | S2: -68.8175 | T2: W | U2: NA | V2: 0.874 | W2: 7.15 | X2: FORK | AA2: Adult | AB2: Unknown | AD2: F | AE2: Yes | AH2: Penobscot River | AI2: 44.68104 | AJ2: -68.8175 | AK2: 42194 | AM2: 8.382 | AR2: Penobscot River | AV2: TRICAINE METHANESULFONATE | AX2: TRICAINE METHANESULFONATE | AY2: SODIUM BICARBONATE
A3: 3D9.1BF1885A15 | B3: Acoustic | C3: VEMCO | D3: V16-4x | E3: 1194446 | F3: 24580 | G3: A69-9001 | H3: INTERNAL | I3: Midventral line incision, sutures | J3: 42194 | K3: 2435 days | L3: Catherine Johnston/Kevin Lachapelle | M3: Gayle Zydlewski | N3: Universtiy of Maine | O3: Shortnose Sturgeon | P3: Acipenser brevirostrum | Q3: Penobscot River | R3: 44.68104 | S3: -68.8175 | T3: W | U3: NA | V3: 0.866 | W3: 6.9 | X3: FORK | AA3: Adult | AB3: Unknown | AD3: F | AE3: Yes | AH3: Penobscot River | AI3: 44.68104 | AJ3: -68.8175 | AK3: 42194 | AM3: 8.2296 | AR3: Penobscot River | AV3: TRICAINE METHANESULFONATE | AX3: TRICAINE METHANESULFONATE | AY3: SODIUM BICARBONATE
A4: 3D9.1BF1886412 | B4: Acoustic | C4: VEMCO | D4: V16-4x | E4: 1147448 | F4: 28161 | G4: A69-9001 | H4: INTERNAL | I4: Midventral line incision, sutures | J4: 42201 | K4: 2993 days | L4: Catherine Johnston/Kevin Lachapelle | M4: Gayle Zydlewski | N4: Universtiy of Maine | O4: Shortnose Sturgeon | P4: Acipenser brevirostrum | Q4: Penobscot River | R4: 44.70229 | S4: -68.83387 | T4: W | U4: NA | V4: 0.922 | W4: 7.7 | X4: FORK | AA4: Adult | AB4: Unknown | AD4: F | AE4: Yes | AH4: Penobscot River | AI4: 44.70229 | AJ4: -68.83387 | AK4: 42201 | AM4: 6.5532 | AR4: Penobscot River | AV4: TRICAINE METHANESULFONATE | AX4: TRICAINE METHANESULFONATE | AY4: SODIUM BICARBONATE
A5: 3D9.1BF1886059 | B5: Acoustic | C5: VEMCO | D5: V16-4x | E5: 1194447 | F5: 24581 | G5: A69-9001 | H5: INTERNAL | I5: Midventral line incision, sutures | J5: 42206 | K5: 2435 days | L5: Catherine Johnston/Kevin Lachapelle | M5: Gayle Zydlewski | N5: Universtiy of Maine | O5: Shortnose Sturgeon | P5: Acipenser brevirostrum | Q5: Penobscot River | R5: 44.68104 | S5: -68.8175 | T5: W | U5: NA | V5: 0.796 | W5: 5.85 | X5: FORK | AA5: Adult | AB5: Unknown | AD5: F | AE5: Yes | AH5: Penobscot River | AI5: 44.68104 | AJ5: -68.8175 | AK5: 42206 | AM5: 8.2296 | AR5: Penobscot River | AV5: TRICAINE METHANESULFONATE | AX5: TRICAINE METHANESULFONATE | AY5: SODIUM BICARBONATE
A6: 3D9.1BF18888EB | B6: Acoustic | C6: VEMCO | D6: V16-4x | E6: 1194440 | F6: 24574 | G6: A69-9001 | H6: INTERNAL | I6: Midventral line incision, sutures | J6: 42206 | K6: 2435 days | L6: Catherine Johnston/Kevin Lachapelle | M6: Gayle Zydlewski | N6: Universtiy of Maine | O6: Shortnose Sturgeon | P6: Acipenser brevirostrum | Q6: Penobscot River | R6: 44.68104 | S6: -68.8175 | T6: W | U6: NA | V6: 0.883 | W6: 5.9 | X6: FORK | AA6: Adult | AB6: Unknown | AD6: F | AE6: Yes | AH6: Penobscot River | AI6: 44.68104 | AJ6: -68.8175 | AK6: 42206 | AM6: 8.2296 | AR6: Penobscot River | AV6: TRICAINE METHANESULFONATE | AX6: TRICAINE METHANESULFONATE | AY6: SODIUM BICARBONATE
A7: 3D9.1BF1887762 | B7: Acoustic | C7: VEMCO | D7: V16-4x | E7: 1194441 | F7: 24575 | G7: A69-9001 | H7: INTERNAL | I7: Midventral line incision, sutures | J7: 42222 | K7: 2435 days | L7: Catherine Johnston/Kevin Lachapelle | M7: Gayle Zydlewski | N7: Universtiy of Maine | O7: Shortnose Sturgeon | P7: Acipenser brevirostrum | Q7: Penobscot River | R7: 44.68104 | S7: -68.8175 | T7: W | U7: NA | V7: 0.934 | W7: 7.5 | X7: FORK | AA7: Adult | AB7: Unknown | AD7: F | AE7: Yes | AH7: Penobscot River | AI7: 44.68104 | AJ7: -68.8175 | AK7: 42222 | AM7: 7.10184 | AR7: Penobscot River | AV7: TRICAINE METHANESULFONATE | AX7: TRICAINE METHANESULFONATE | AY7: SODIUM BICARBONATE
A8: 3D9.1BF18894AE | B8: Acoustic | C8: VEMCO | D8: V16-4x | E8: 1221724 | F8: 21257 | G8: A69-9001 | H8: INTERNAL | I8: Midventral line incision, sutures | J8: 42223 | K8: 2435 days | L8: Catherine Johnston/Kevin Lachapelle | M8: Gayle Zydlewski | N8: Universtiy of Maine | O8: Shortnose Sturgeon | P8: Acipenser brevirostrum | Q8: Penobscot River | R8: 44.70229 | S8: -68.83387 | T8: W | U8: NA | V8: 0.948 | W8: 7.5 | X8: FORK | AA8: Adult | AB8: Unknown | AD8: F | AE8: Yes | AH8: Penobscot River | AI8: 44.70229 | AJ8: -68.83387 | AK8: 42223 | AM8: 5.1816 | AR8: Penobscot River | AV8: TRICAINE METHANESULFONATE | AX8: TRICAINE METHANESULFONATE | AY8: SODIUM BICARBONATE
A9: 3D9.1BF1885B77 | B9: Acoustic | C9: VEMCO | D9: V16-4x | E9: 1221719 | F9: 21252 | G9: A69-9001 | H9: INTERNAL | I9: Midventral line incision, sutures | J9: 42223 | K9: 2435 days | L9: Catherine Johnston/Kevin Lachapelle | M9: Gayle Zydlewski | N9: Universtiy of Maine | O9: Shortnose Sturgeon | P9: Acipenser brevirostrum | Q9: Penobscot River | R9: 44.70229 | S9: -68.83387 | T9: W | U9: NA | V9: 0.92 | W9: 9.6 | X9: FORK | AA9: Adult | AB9: Unknown | AD9: F | AE9: Yes | AH9: Penobscot River | AI9: 44.70229 | AJ9: -68.83387 | AK9: 42223 | AM9: 5.4864 | AR9: Penobscot River | AV9: TRICAINE METHANESULFONATE | AX9: TRICAINE METHANESULFONATE | AY9: SODIUM BICARBONATE
A10: 3D9.1BF188950C | B10: Acoustic | C10: VEMCO | D10: V16-4x | E10: 1221720 | F10: 21253 | G10: A69-9001 | H10: INTERNAL | I10: Midventral line incision, sutures | J10: 42236 | K10: 2435 days | L10: Catherine Johnston/Kevin Lachapelle | M10: Gayle Zydlewski | N10: Universtiy of Maine | O10: Shortnose Sturgeon | P10: Acipenser brevirostrum | Q10: Penobscot River | R10: 44.70229 | S10: -68.83387 | T10: W | U10: NA | V10: 0.925 | W10: 7.1 | X10: FORK | AA10: Adult | AB10: Unknown | AD10: F | AE10: Yes | AH10: Penobscot River | AI10: 44.70229 | AJ10: -68.83387 | AK10: 42236 | AM10: 5.1816 | AR10: Penobscot River | AV10: TRICAINE METHANESULFONATE | AX10: TRICAINE METHANESULFONATE | AY10: SODIUM BICARBONATE
A11: 3D9.1BF188646D | B11: Acoustic | C11: VEMCO | D11: V16-4x | E11: 1221723 | F11: 21256 | G11: A69-9001 | H11: INTERNAL | I11: Midventral line incision, sutures | J11: 42250 | K11: 2435 days | L11: Catherine Johnston/Kevin Lachapelle | M11: Gayle Zydlewski | N11: Universtiy of Maine | O11: Shortnose Sturgeon | P11: Acipenser brevirostrum | Q11: Penobscot River | R11: 44.77563 | S11: -68.78451 | T11: W | U11: NA | V11: 0.91 | W11: 5.4 | X11: FORK | AA11: Adult | AB11: Unknown | AD11: F | AE11: Yes | AH11: Penobscot River | AI11: 44.77563 | AJ11: -68.78451 | AK11: 42250 | AM11: 6.00456 | AR11: Penobscot River | AV11: TRICAINE METHANESULFONATE | AX11: TRICAINE METHANESULFONATE | AY11: SODIUM BICARBONATE
A12: 3D9.1BF1887023 | B12: Acoustic | C12: VEMCO | D12: V16-4x | E12: 1221733 | F12: 21266 | G12: A69-9001 | H12: INTERNAL | I12: Midventral line incision, sutures | J12: 42250 | K12: 2435 days | L12: Catherine Johnston/Kevin Lachapelle | M12: Gayle Zydlewski | N12: Universtiy of Maine | O12: Shortnose Sturgeon | P12: Acipenser brevirostrum | Q12: Penobscot River | R12: 44.77563 | S12: -68.78451 | T12: W | U12: NA | V12: 0.826 | W12: 4.7 | X12: FORK | AA12: Adult | AB12: Unknown | AD12: F | AE12: Yes | AH12: Penobscot River | AI12: 44.77563 | AJ12: -68.78451 | AK12: 42250 | AM12: 6.64464 | AR12: Penobscot River | AV12: TRICAINE METHANESULFONATE | AX12: TRICAINE METHANESULFONATE | AY12: SODIUM BICARBONATE
A13: 3D9.1C2D8D20D0 | B13: Acoustic | C13: VEMCO | D13: V16-4x | E13: 1221721 | F13: 21254 | G13: A69-9001 | H13: INTERNAL | I13: Midventral line incision, sutures | J13: 42250 | K13: 2435 days | L13: Catherine Johnston/Kevin Lachapelle | M13: Gayle Zydlewski | N13: Universtiy of Maine | O13: Shortnose Sturgeon | P13: Acipenser brevirostrum | Q13: Penobscot River | R13: 44.77563 | S13: -68.78451 | T13: W | U13: NA | V13: 0.979 | W13: 10 | X13: FORK | AA13: Adult | AB13: Unknown | AD13: F | AE13: Yes | AH13: Penobscot River | AI13: 44.77563 | AJ13: -68.78451 | AK13: 42250 | AM13: 7.95528 | AR13: Penobscot River | AV13: TRICAINE METHANESULFONATE | AX13: TRICAINE METHANESULFONATE | AY13: SODIUM BICARBONATE
... A46: 3DD.003C0103E4 | B46: Acoustic | C46: VEMCO | D46: V16T-4x | E46: 1251361 | F46: 11182 | G46: A69-9002 | H46: INTERNAL | I46: Midventral line incision, sutures | J46: 43655 | K46: 2427 days | L46: Joe Zydlewski | M46: Gayle Zydlewski | N46: Universtiy of Maine | O46: Shortnose Sturgeon | P46: Acipenser brevirostrum | Q46: Penobscot River | R46: 44.94181 | S46: -68.64457 | T46: W | U46: NA | V46: 0.54 | W46: 0.85 | X46: FORK | AA46: Sub-Adult | AB46: Unknown | AD46: U | AE46: Yes | AH46: Penobscot River | AI46: 44.93041 | AJ46: -68.6401 | AK46: 43655 | AM46: 0 | AR46: Penobscot River | AV46: TRICAINE METHANESULFONATE | AX46: TRICAINE METHANESULFONATE | AY46: SODIUM BICARBONATE
A47: 3DD.003BEF357E | B47: Acoustic | C47: VEMCO | D47: V16T-4x | E47: 1251362 | F47: 11183 | G47: A69-9002 | H47: INTERNAL | I47: Midventral line incision, sutures | J47: 44018 | K47: 2427 days | L47: Joe Zydlewski | M47: Gayle Zydlewski | N47: Universtiy of Maine | O47: Shortnose Sturgeon | P47: Acipenser brevirostrum | Q47: Penobscot River | R47: 44.942021 | S47: -68.644818 | T47: W | U47: NA | V47: =tid.cln!T2/100 -> 0.77 | W47: =tid.cln!W2 -> 3.45 | X47: FORK | AB47: Unknown | AD47: U | AE47: Yes | AH47: =Q47 -> Penobscot River | AI47: =R47 -> 44.942021 | AJ47: =S47 -> -68.644818 | AK47: 44018 | AR47: =AH47 -> Penobscot River | AV47: TRICAINE METHANESULFONATE | AX47: TRICAINE METHANESULFONATE | AY47: SODIUM BICARBONATE
A48: 3DD.003E185F8D | B48: Acoustic | C48: VEMCO | D48: V16-4x-BLU-1 | E48: =_xlfn.XLOOKUP(F48, Sheet2!F$2:F$51,Sheet2!J$2:J$51,"") -> 1638355 | F48: 201127 | G48: A69-2801 | H48: INTERNAL | I48: Midventral line incision, sutures | J48: 45867 | K48: 2560 days | L48: Joe Zydlewski / Sander Elliott | M48: Joe Zydlewski | N48: USGS Maine CFWRU | O48: Atlantic Sturgeon | P48: Acipenser oxyrinchus | Q48: Kennebec River | R48: 44.241953 | S48: -69.767512 | T48: W | U48: NA | V48: =tid.cln!T3/100 -> 1.56 | W48: U | X48: FORK | AB48: Unknown | AD48: U | AE48: Yes | AH48: =Q48 -> Kennebec River | AI48: =R48 -> 44.241953 | AJ48: =S48 -> -69.767512 | AK48: 45867 | AR48: =AH48 -> Kennebec River | AV48: TRICAINE METHANESULFONATE | AX48: TRICAINE METHANESULFONATE | AY48: SODIUM BICARBONATE
A49: 3DD.003E185F8F | B49: Acoustic | C49: VEMCO | D49: V16-4x-BLU-1 | E49: =_xlfn.XLOOKUP(F49, Sheet2!F$2:F$51,Sheet2!J$2:J$51,"") -> 1638356 | F49: 201128 | G49: A69-2801 | H49: INTERNAL | I49: Midventral line incision, sutures | J49: 45867 | K49: 2560 days | L49: Joe Zydlewski / Sander Elliott | M49: Joe Zydlewski | N49: USGS Maine CFWRU | O49: Atlantic Sturgeon | P49: Acipenser oxyrinchus | Q49: Kennebec River | R49: 44.241953 | S49: -69.767512 | T49: W | U49: NA | V49: =tid.cln!T4/100 -> 1.74 | W49: U | X49: FORK | AB49: Unknown | AD49: U | AE49: Yes | AH49: =Q49 -> Kennebec River | AI49: =R49 -> 44.241953 | AJ49: =S49 -> -69.767512 | AK49: 45867 | AR49: =AH49 -> Kennebec River | AV49: TRICAINE METHANESULFONATE | AX49: TRICAINE METHANESULFONATE | AY49: SODIUM BICARBONATE
A50: 3DD.003E185F76 | B50: Acoustic | C50: VEMCO | D50: V16-4x-BLU-1 | E50: =_xlfn.XLOOKUP(F50, Sheet2!F$2:F$51,Sheet2!J$2:J$51,"") -> 1638358 | F50: 201130 | G50: A69-2801 | H50: INTERNAL | I50: Midventral line incision, sutures | J50: 45867 | K50: 2560 days | L50: Joe Zydlewski / Sander Elliott | M50: Joe Zydlewski | N50: USGS Maine CFWRU | O50: Atlantic Sturgeon | P50: Acipenser oxyrinchus | Q50: Kennebec River | R50: 44.241953 | S50: -69.767512 | T50: W | U50: NA | V50: =tid.cln!T5/100 -> 1.34 | W50: U | X50: FORK | AB50: Unknown | AD50: U | AE50: Yes | AH50: =Q50 -> Kennebec River | AI50: =R50 -> 44.241953 | AJ50: =S50 -> -69.767512 | AK50: 45867 | AR50: =AH50 -> Kennebec River | AV50: TRICAINE METHANESULFONATE | AX50: TRICAINE METHANESULFONATE | AY50: SODIUM BICARBONATE
A51: 3DD.003E185F77 | B51: Acoustic | C51: VEMCO | D51: V16-4x-BLU-1 | E51: =_xlfn.XLOOKUP(F51, Sheet2!F$2:F$51,Sheet2!J$2:J$51,"") -> 1638359 | F51: 201131 | G51: A69-2801 | H51: INTERNAL | I51: Midventral line incision, sutures | J51: 45867 | K51: 2560 days | L51: Joe Zydlewski / Sander Elliott | M51: Joe Zydlewski | N51: USGS Maine CFWRU | O51: Atlantic Sturgeon | P51: Acipenser oxyrinchus | Q51: Kennebec River | R51: 44.241953 | S51: -69.767512 | T51: W | U51: NA | V51: =tid.cln!T6/100 -> 1.56 | W51: U | X51: FORK | AB51: Unknown | AD51: U | AE51: Yes | AH51: =Q51 -> Kennebec River | AI51: =R51 -> 44.241953 | AJ51: =S51 -> -69.767512 | AK51: 45867 | AR51: =AH51 -> Kennebec River | AV51: TRICAINE METHANESULFONATE | AX51: TRICAINE METHANESULFONATE | AY51: SODIUM BICARBONATE
A52: 3DD.003E185F92 | B52: Acoustic | C52: VEMCO | D52: V16-4x-BLU-1 | E52: =_xlfn.XLOOKUP(F52, Sheet2!F$2:F$51,Sheet2!J$2:J$51,"") -> 1638360 | F52: 201132 | G52: A69-2801 | H52: INTERNAL | I52: Midventral line incision, sutures | J52: 45867 | K52: 2560 days | L52: Joe Zydlewski / Sander Elliott | M52: Joe Zydlewski | N52: USGS Maine CFWRU | O52: Atlantic Sturgeon | P52: Acipenser oxyrinchus | Q52: Kennebec River | R52: 44.241953 | S52: -69.767512 | T52: W | U52: NA | V52: =tid.cln!T7/100 -> 1.49 | W52: U | X52: FORK | AB52: Unknown | AD52: U | AE52: Yes | AH52: =Q52 -> Kennebec River | AI52: =R52 -> 44.241953 | AJ52: =S52 -> -69.767512 | AK52: 45867 | AR52: =AH52 -> Kennebec River | AV52: TRICAINE METHANESULFONATE | AX52: TRICAINE METHANESULFONATE | AY52: SODIUM BICARBONATE
A53: 3DD.003E185F8C | B53: Acoustic | C53: VEMCO | D53: V16-4x-BLU-1 | E53: =_xlfn.XLOOKUP(F53, Sheet2!F$2:F$51,Sheet2!J$2:J$51,"") -> 1638361 | F53: 201133 | G53: A69-2801 | H53: INTERNAL | I53: Midventral line incision, sutures | J53: 45867 | K53: 2560 days | L53: Joe Zydlewski / Sander Elliott | M53: Joe Zydlewski | N53: USGS Maine CFWRU | O53: Atlantic Sturgeon | P53: Acipenser oxyrinchus | Q53: Kennebec River | R53: 44.241953 | S53: -69.767512 | T53: W | U53: NA | V53: =tid.cln!T8/100 -> 1.38 | W53: U | X53: FORK | AB53: Unknown | AD53: U | AE53: Yes | AH53: =Q53 -> Kennebec River | AI53: =R53 -> 44.241953 | AJ53: =S53 -> -69.767512 | AK53: 45867 | AR53: =AH53 -> Kennebec River | AV53: TRICAINE METHANESULFONATE | AX53: TRICAINE METHANESULFONATE | AY53: SODIUM BICARBONATE
A54: 3DD.003E185F93 | B54: Acoustic | C54: VEMCO | D54: V16-4x-BLU-1 | E54: =_xlfn.XLOOKUP(F54, Sheet2!F$2:F$51,Sheet2!J$2:J$51,"") -> 1638362 | F54: 201134 | G54: A69-2801 | H54: INTERNAL | I54: Midventral line incision, sutures | J54: 45867 | K54: 2560 days | L54: Joe Zydlewski / Sander Elliott | M54: Joe Zydlewski | N54: USGS Maine CFWRU | O54: Atlantic Sturgeon | P54: Acipenser oxyrinchus | Q54: Kennebec River | R54: 44.241953 | S54: -69.767512 | T54: W | U54: NA | V54: =tid.cln!T9/100 -> 1.16 | W54: U | X54: FORK | AB54: Unknown | AD54: U | AE54: Yes | AH54: =Q54 -> Kennebec River | AI54: =R54 -> 44.241953 | AJ54: =S54 -> -69.767512 | AK54: 45867 | AR54: =AH54 -> Kennebec River | AV54: TRICAINE METHANESULFONATE | AX54: TRICAINE METHANESULFONATE | AY54: SODIUM BICARBONATE
A55: 3DD.003E185F95 | B55: Acoustic | C55: VEMCO | D55: V16-4x-BLU-1 | E55: =_xlfn.XLOOKUP(F55, Sheet2!F$2:F$51,Sheet2!J$2:J$51,"") -> 1645258 | F55: 201212 | G55: A69-2801 | H55: INTERNAL | I55: Midventral line incision, sutures | J55: 45867 | K55: 2560 days | L55: Joe Zydlewski / Sander Elliott | M55: Joe Zydlewski | N55: USGS Maine CFWRU | O55: Atlantic Sturgeon | P55: Acipenser oxyrinchus | Q55: Kennebec River | R55: 44.241953 | S55: -69.767512 | T55: W | U55: NA | V55: =tid.cln!T10/100 -> 1.47 | W55: U | X55: FORK | AB55: Unknown | AD55: M | AE55: Yes | AH55: =Q55 -> Kennebec River | AI55: =R55 -> 44.241953 | AJ55: =S55 -> -69.767512 | AK55: 45867 | AR55: =AH55 -> Kennebec River | AV55: TRICAINE METHANESULFONATE | AX55: TRICAINE METHANESULFONATE | AY55: SODIUM BICARBONATE
A56: 3DD.003E185F86 | B56: Acoustic | C56: VEMCO | D56: V16-4x-BLU-1 | E56: =_xlfn.XLOOKUP(F56, Sheet2!F$2:F$51,Sheet2!J$2:J$51,"") -> 1645261 | F56: 201215 | G56: A69-2801 | H56: INTERNAL | I56: Midventral line incision, sutures | J56: 45867 | K56: 2560 days | L56: Joe Zydlewski / Sander Elliott | M56: Joe Zydlewski | N56: USGS Maine CFWRU | O56: Atlantic Sturgeon | P56: Acipenser oxyrinchus | Q56: Kennebec River | R56: 44.241953 | S56: -69.767512 | T56: W | U56: NA | V56: =tid.cln!T11/100 -> 1.43 | W56: U | X56: FORK | AB56: Unknown | AD56: M | AE56: Yes | AH56: =Q56 -> Kennebec River | AI56: =R56 -> 44.241953 | AJ56: =S56 -> -69.767512 | AK56: 45867 | AR56: =AH56 -> Kennebec River | AV56: TRICAINE METHANESULFONATE | AX56: TRICAINE METHANESULFONATE | AY56: SODIUM BICARBONATE
A57: 3D9.257C65BA2C | B57: Acoustic | C57: VEMCO | D57: V16-4x-BLU-1 | E57: =_xlfn.XLOOKUP(F57, Sheet2!F$2:F$51,Sheet2!J$2:J$51,"") -> 1645274 | F57: 201228 | G57: A69-2801 | H57: INTERNAL | I57: Midventral line incision, sutures | J57: 45867 | K57: 2560 days | L57: Joe Zydlewski / Sander Elliott | M57: Joe Zydlewski | N57: USGS Maine CFWRU | O57: Atlantic Sturgeon | P57: Acipenser oxyrinchus | Q57: Kennebec River | R57: 44.241953 | S57: -69.767512 | T57: W | U57: NA | V57: =tid.cln!T12/100 -> 1.97 | W57: U | X57: FORK | AB57: Unknown | AD57: U | AE57: Yes | AH57: =Q57 -> Kennebec River | AI57: =R57 -> 44.241953 | AJ57: =S57 -> -69.767512 | AK57: 45867 | AR57: =AH57 -> Kennebec River | AV57: TRICAINE METHANESULFONATE | AX57: TRICAINE METHANESULFONATE | AY57: SODIUM BICARBONATE
A58: 3DD.003E185F78 | B58: Acoustic | C58: VEMCO | D58: V16-4x-BLU-1 | E58: =_xlfn.XLOOKUP(F58, Sheet2!F$2:F$51,Sheet2!J$2:J$51,"") -> 1638357 | F58: 201129 | G58: A69-2801 | H58: INTERNAL | I58: Midventral line incision, sutures | J58: 45873 | K58: 2560 days | L58: Joe Zydlewski / Sander Elliott | M58: Joe Zydlewski | N58: USGS Maine CFWRU | O58: Shortnose Sturgeon | P58: Acipenser brevirostrum | Q58: Kennebec River | R58: 44.27189 | S58: -69.785757 | T58: W | U58: NA | V58: =tid.cln!T13/100 -> 0.74 | W58: U | X58: FORK | AB58: Unknown | AD58: U | AE58: Yes | AH58: =Q58 -> Kennebec River | AI58: =R58 -> 44.27189 | AJ58: =S58 -> -69.785757 | AK58: 45873 | AR58: =AH58 -> Kennebec River | AV58: TRICAINE METHANESULFONATE | AX58: TRICAINE METHANESULFONATE | AY58: SODIUM BICARBONATE
A59: 3DD.003E185F88 | B59: Acoustic | C59: VEMCO | D59: V16-4x-BLU-1 | E59: =_xlfn.XLOOKUP(F59, Sheet2!F$2:F$51,Sheet2!J$2:J$51,"") -> 1645259 | F59: 201213 | G59: A69-2801 | H59: INTERNAL | I59: Midventral line incision, sutures | J59: 45873 | K59: 2560 days | L59: Joe Zydlewski / Sander Elliott | M59: Joe Zydlewski | N59: USGS Maine CFWRU | O59: Shortnose Sturgeon | P59: Acipenser brevirostrum | Q59: Kennebec River | R59: 44.27189 | S59: -69.785757 | T59: W | U59: NA | V59: =tid.cln!T14/100 -> 0.59 | W59: U | X59: FORK | AB59: Unknown | AD59: U | AE59: Yes | AH59: =Q59 -> Kennebec River | AI59: =R59 -> 44.27189 | AJ59: =S59 -> -69.785757 | AK59: 45873 | AR59: =AH59 -> Kennebec River | AV59: TRICAINE METHANESULFONATE | AX59: TRICAINE METHANESULFONATE | AY59: SODIUM BICARBONATE
... A97: 3DD.003E185F39 | B97: Acoustic | C97: VEMCO | D97: V16-4x-BLU-1 | E97: =_xlfn.XLOOKUP(F97, Sheet2!F$2:F$51,Sheet2!J$2:J$51,"") -> 1645299 | F97: 201253 | G97: A69-2801 | H97: INTERNAL | I97: Midventral line incision, sutures | J97: 45887 | K97: 2560 days | L97: Joe Zydlewski / Sander Elliott | M97: Joe Zydlewski | N97: USGS Maine CFWRU | O97: Atlantic Sturgeon | P97: Acipenser oxyrinchus | Q97: Penobscot River | R97: 44.686268 | S97: -68.817097 | T97: W | U97: NA | V97: =tid.cln!T52/100 -> 1.09 | W97: U | X97: FORK | AB97: Unknown | AD97: U | AE97: Yes | AH97: =Q97 -> Penobscot River | AI97: =R97 -> 44.686268 | AJ97: =S97 -> -68.817097 | AK97: 45887 | AR97: =AH97 -> Penobscot River | AV97: TRICAINE METHANESULFONATE | AX97: TRICAINE METHANESULFONATE | AY97: SODIUM BICARBONATE

Sheet tid.cln
A1: FishID | B1: CaptureDate | C1: PITIDNo | D1: AcousticSerialNo | E1: AcousticTagFamily | F1: AcousticCodeSpace | G1: AcousticIDCode | H1: EstTagLife | I1: DeathDate | J1: SalesOrder | K1: Customer | L1: CodeSpace | M1: IDCode | N1: Species | O1: Origin | P1: FishIDs | Q1: ProjectID | R1: ReleaseSite | S1: CaptureLocation | T1: ForkLength | U1: TotalLength | V1: LengthUnit | W1: Mass | X1: MassUnit | Y1: Alive | Z1: Recapture | AA1: InitialRelease | AB1: Sex | AC1: Interorbital | AD1: InsideMouth | AE1: OutsideMouth | AF1: SensorIDCode | AG1: SensorCodeSpace | AH1: System | AI1: Notes | AJ1: TagID | AK1: longitude | AL1: latitude
A2: SNS-2016-116 | B2: 44018 | C2: 3DD.003BEF357E | D2: 1251362 | E2: V16T-4x | F2: A69-9002 | G2: 11183 | H2: 2427 | I2: 0 | J2: 21840 | K2: The Nature Conservancy | L2: 9002 | M2: 11183 | N2: SNS | O2: Wild | P2: FLOY: 53046; Genetic ID: G-1433; Photo ID: 16-178; | Q2: Sturgeon-PNR | R2: Penobscot River | S2: Penobscot River | T2: 77 | U2: 91 | V2: cm | W2: 3.45 | X2: kg | Y2: 1 | Z2: 1 | AA2: 0 | AF2: 11183 | AG2: 9002 | AH2: Penobscot | AJ2: A69-9002-11183 | AK2: -68.644818 | AL2: 44.942021
A3: 2025-AST-0002 | B3: 45867 | C3: 3DD.003E185F8D | F3: A69-2801 | G3: 201127 | H3: 2560 | I3: 0 | N3: AST | O3: Wild | S3: Gardiner | T3: 156 | U3: 179 | V3: cm | X3: g | Y3: 1 | Z3: 0 | AA3: 1 | AB3: UNK | AC3: 138 | AD3: 61 | AE3: 101 | AH3: Kennebec | AJ3: A69-2801-201127 | AK3: -69.767512 | AL3: 44.241953
A4: 2025-AST-0004 | B4: 45867 | C4: 3DD.003E185F8F | F4: A69-2801 | G4: 201128 | H4: 2560 | I4: 0 | N4: AST | O4: Wild | S4: Gardiner | T4: 174 | U4: 194 | V4: cm | X4: g | Y4: 1 | Z4: 0 | AA4: 1 | AB4: UNK | AD4: 53 | AE4: 87 | AH4: Kennebec | AJ4: A69-2801-201128 | AK4: -69.767512 | AL4: 44.241953
A5: 2025-AST-0006 | B5: 45867 | C5: 3DD.003E185F76 | F5: A69-2801 | G5: 201130 | H5: 2560 | I5: 0 | N5: AST | O5: Wild | S5: Gardiner | T5: 134 | U5: 149 | V5: cm | X5: g | Y5: 1 | Z5: 0 | AA5: 1 | AB5: UNK | AC5: 110 | AD5: 48 | AE5: 75 | AH5: Kennebec | AJ5: A69-2801-201130 | AK5: -69.767512 | AL5: 44.241953
A6: 2025-AST-0005 | B6: 45867 | C6: 3DD.003E185F77 | F6: A69-2801 | G6: 201131 | H6: 2560 | I6: 0 | N6: AST | O6: Wild | S6: Gardiner | T6: 156 | U6: 177 | V6: cm | X6: g | Y6: 1 | Z6: 0 | AA6: 1 | AB6: UNK | AC6: 127 | AD6: 56 | AE6: 89 | AH6: Kennebec | AJ6: A69-2801-201131 | AK6: -69.767512 | AL6: 44.241953
A7: 2025-AST-0007 | B7: 45867 | C7: 3DD.003E185F92 | F7: A69-2801 | G7: 201132 | H7: 2560 | I7: 0 | N7: AST | O7: Wild | S7: Gardiner | T7: 149 | U7: 173 | V7: cm | X7: g | Y7: 1 | Z7: 0 | AA7: 1 | AB7: UNK | AC7: 127 | AD7: 46 | AE7: 71 | AH7: Kennebec | AJ7: A69-2801-201132 | AK7: -69.767512 | AL7: 44.241953
A8: 2025-AST-0001 | B8: 45867 | C8: 3DD.003E185F8C | F8: A69-2801 | G8: 201133 | H8: 2560 | I8: 0 | N8: AST | O8: Wild | S8: Gardiner | T8: 138 | U8: 158 | V8: cm | X8: g | Y8: 1 | Z8: 0 | AA8: 1 | AB8: UNK | AC8: 102 | AD8: 33 | AE8: 61 | AH8: Kennebec | AJ8: A69-2801-201133 | AK8: -69.767512 | AL8: 44.241953
A9: 2025-AST-0003 | B9: 45867 | C9: 3DD.003E185F93 | F9: A69-2801 | G9: 201134 | H9: 2560 | I9: 0 | N9: AST | O9: Wild | S9: Gardiner | T9: 116 | U9: 179 | V9: cm | X9: g | Y9: 1 | Z9: 0 | AA9: 1 | AB9: UNK | AC9: 138 | AD9: 41 | AE9: 71 | AH9: Kennebec | AJ9: A69-2801-201134 | AK9: -69.767512 | AL9: 44.241953
A10: 2025-AST-0008 | B10: 45867 | C10: 3DD.003E185F95 | F10: A69-2801 | G10: 201212 | H10: 2560 | I10: 0 | N10: AST | O10: Wild | S10: Gardiner | T10: 147 | U10: 170 | V10: cm | X10: g | Y10: 1 | Z10: 0 | AA10: 1 | AB10: M | AC10: 117 | AD10: 50 | AE10: 71 | AH10: Kennebec | AI10: Milt | AJ10: A69-2801-201212 | AK10: -69.767512 | AL10: 44.241953
A11: 2025-AST-0009 | B11: 45867 | C11: 3DD.003E185F86 | F11: A69-2801 | G11: 201215 | H11: 2560 | I11: 0 | N11: AST | O11: Wild | S11: Gardiner | T11: 143 | U11: 166 | V11: cm | X11: g | Y11: 1 | Z11: 0 | AA11: 1 | AB11: M | AC11: 117 | AD11: 55 | AE11: 71 | AH11: Kennebec | AI11: Milt | AJ11: A69-2801-201215 | AK11: -69.767512 | AL11: 44.241953
A12: AST-2007-025 | B12: 45867 | C12: 3D9.257C65BA2C | F12: A69-2801 | G12: 201228 | H12: 2560 | I12: 0 | N12: AST | O12: Wild | P12: Carlin: 31449; Genetic ID: G-154; Photo ID: 07-088; | Q12: Sturgeon-PNR | R12: Penobscot River | S12: Gardiner | T12: 197 | U12: 225 | V12: cm | X12: g | Y12: 1 | Z12: 1 | AA12: 0 | AB12: UNK | AD12: 74 | AE12: 102 | AH12: Kennebec | AJ12: A69-2801-201228 | AK12: -69.767512 | AL12: 44.241953
A13: 2025-SNS-0006 | B13: 45873 | C13: 3DD.003E185F78 | F13: A69-2801 | G13: 201129 | H13: 2560 | I13: 0 | N13: SNS | O13: Wild | S13: Hallowell | T13: 74 | U13: 84 | V13: cm | X13: g | Y13: 1 | Z13: 0 | AA13: 1 | AB13: UNK | AC13: 57 | AD13: 44 | AE13: 55 | AH13: Kennebec | AI13: CAUDAL DEFORMITY | AJ13: A69-2801-201129 | AK13: -69.785757 | AL13: 44.27189
A14: 2025-SNS-0011 | B14: 45873 | C14: 3DD.003E185F88 | F14: A69-2801 | G14: 201213 | H14: 2560 | I14: 0 | N14: SNS | O14: Wild | S14: Hallowell | T14: 59 | U14: 69 | V14: cm | X14: g | Y14: 1 | Z14: 0 | AA14: 1 | AB14: UNK | AC14: 47 | AD14: 36 | AE14: 42 | AH14: Kennebec | AJ14: A69-2801-201213 | AK14: -69.785757 | AL14: 44.27189
A15: 2025-SNS-0010 | B15: 45873 | C15: 3DD.003E185F8E | F15: A69-2801 | G15: 201214 | H15: 2560 | I15: 0 | N15: SNS | O15: Wild | S15: Hallowell | T15: 58 | U15: 70 | V15: cm | X15: g | Y15: 1 | Z15: 0 | AA15: 1 | AB15: UNK | AC15: 51 | AD15: 35 | AE15: 43 | AH15: Kennebec | AJ15: A69-2801-201214 | AK15: -69.785757 | AL15: 44.27189
A16: 2025-SNS-0003 | B16: 45873 | C16: 3DD.003E185F74 | F16: A69-2801 | G16: 201216 | H16: 2560 | I16: 0 | N16: SNS | O16: Wild | S16: Hallowell | T16: 65 | U16: 76 | V16: cm | X16: g | Y16: 1 | Z16: 0 | AA16: 1 | AB16: UNK | AC16: 51 | AD16: 40 | AE16: 47 | AH16: Kennebec | AJ16: A69-2801-201216 | AK16: -69.785757 | AL16: 44.27189
A17: 2025-SNS-0009 | B17: 45873 | C17: 3DD.003E185F89 | F17: A69-2801 | G17: 201217 | H17: 2560 | I17: 0 | N17: SNS | O17: Wild | S17: Hallowell | T17: 68 | U17: 82 | V17: cm | X17: g | Y17: 1 | Z17: 0 | AA17: 1 | AB17: UNK | AC17: 51 | AD17: 44 | AE17: 52 | AH17: Kennebec | AJ17: A69-2801-201217 | AK17: -69.785757 | AL17: 44.27189
A18: 2025-SNS-0002 | B18: 45873 | C18: 3DD.003E185F94 | F18: A69-2801 | G18: 201218 | H18: 2560 | I18: 0 | N18: SNS | O18: Wild | S18: Hallowell | T18: 68 | U18: 82 | V18: cm | X18: g | Y18: 1 | Z18: 0 | AA18: 1 | AB18: UNK | AC18: 57 | AD18: 38 | AE18: 46 | AH18: Kennebec | AJ18: A69-2801-201218 | AK18: -69.785757 | AL18: 44.27189
A19: 2025-SNS-0001 | B19: 45873 | C19: 3DD.003E185F7F | F19: A69-2801 | G19: 201219 | H19: 2560 | I19: 0 | N19: SNS | O19: Wild | S19: Hallowell | T19: 73 | U19: 88 | V19: cm | X19: g | Y19: 1 | Z19: 0 | AA19: 1 | AB19: UNK | AC19: 54 | AD19: 36 | AE19: 41 | AH19: Kennebec | AJ19: A69-2801-201219 | AK19: -69.785757 | AL19: 44.27189
A20: 2025-SNS-0005 | B20: 45873 | C20: 3DD.003E185F90 | F20: A69-2801 | G20: 201220 | H20: 2560 | I20: 0 | N20: SNS | O20: Wild | S20: Hallowell | T20: 65 | U20: 77 | V20: cm | X20: g | Y20: 1 | Z20: 0 | AA20: 1 | AB20: UNK | AC20: 50 | AD20: 36 | AE20: 43 | AH20: Kennebec | AI20: WOUND L | AJ20: A69-2801-201220 | AK20: -69.785757 | AL20: 44.27189
A21: 2025-SNS-0004 | B21: 45873 | C21: 3DD.003E185F91 | F21: A69-2801 | G21: 201221 | H21: 2560 | I21: 0 | N21: SNS | O21: Wild | S21: Hallowell | T21: 75 | U21: 86 | V21: cm | X21: g | Y21: 1 | Z21: 0 | AA21: 1 | AB21: UNK | AC21: 59 | AD21: 46 | AE21: 54 | AH21: Kennebec | AI21: NO RIGHT PEC | AJ21: A69-2801-201221 | AK21: -69.785757 | AL21: 44.27189
A22: 2025-SNS-0008 | B22: 45873 | C22: 3DD.003E185F6C | F22: A69-2801 | G22: 201222 | H22: 2560 | I22: 0 | N22: SNS | O22: Wild | S22: Hallowell | T22: 70 | U22: 82 | V22: cm | X22: g | Y22: 1 | Z22: 0 | AA22: 1 | AB22: UNK | AC22: 52 | AD22: 44 | AE22: 51 | AH22: Kennebec | AJ22: A69-2801-201222 | AK22: -69.785757 | AL22: 44.27189
A23: 2025-SNS-0007 | B23: 45873 | C23: 3DD.003E185F87 | F23: A69-2801 | G23: 201223 | H23: 2560 | I23: 0 | N23: SNS | O23: Wild | S23: Hallowell | T23: 65 | U23: 76 | V23: cm | X23: g | Y23: 1 | Z23: 0 | AA23: 1 | AB23: UNK | AC23: 49 | AD23: 37 | AE23: 46 | AH23: Kennebec | AJ23: A69-2801-201223 | AK23: -69.785757 | AL23: 44.27189
A24: 2025-SNS-0013 | B24: 45873 | C24: 3DD.003E185F68 | F24: A69-2801 | G24: 201224 | H24: 2560 | I24: 0 | N24: SNS | O24: Wild | S24: Hallowell | T24: 65 | U24: 77 | V24: cm | X24: g | Y24: 1 | Z24: 0 | AA24: 1 | AB24: UNK | AC24: 51 | AD24: 57 | AE24: 45 | AH24: Kennebec | AJ24: A69-2801-201224 | AK24: -69.785757 | AL24: 44.27189
A25: 2025-SNS-0012 | B25: 45873 | C25: 3DD.003E185F85 | F25: A69-2801 | G25: 201225 | H25: 2560 | I25: 0 | N25: SNS | O25: Wild | S25: Hallowell | T25: 63 | U25: 75 | V25: cm | X25: g | Y25: 1 | Z25: 0 | AA25: 1 | AB25: UNK | AC25: 46 | AD25: 35 | AE25: 43 | AH25: Kennebec | AJ25: A69-2801-201225 | AK25: -69.785757 | AL25: 44.27189
A26: 2025-AST-0013 | B26: 45874 | C26: 3DD.003E185F81 | F26: A69-2801 | G26: 201229 | H26: 2560 | I26: 0 | N26: AST | O26: Wild | S26: The Spindle | T26: 159 | U26: 185 | V26: cm | X26: g | Y26: 1 | Z26: 0 | AA26: 1 | AB26: UNK | AC26: 120 | AD26: 59 | AE26: 85 | AH26: Penobscot | AJ26: A69-2801-201229 | AK26: -68.817097 | AL26: 44.686268
A27: 2025-AST-0014 | B27: 45874 | C27: 3DD.003E185F7A | F27: A69-2801 | G27: 201233 | H27: 2560 | I27: 0 | N27: AST | O27: Wild | S27: The Spindle | T27: 90 | U27: 105 | V27: cm | X27: g | Y27: 1 | Z27: 0 | AA27: 1 | AB27: UNK | AC27: 73 | AD27: 39 | AE27: 52 | AH27: Penobscot | AJ27: A69-2801-201233 | AK27: -68.817097 | AL27: 44.686268
A28: 2025-AST-0015 | B28: 45874 | C28: 3DD.003E185F83 | F28: A69-2801 | G28: 201240 | H28: 2560 | I28: 0 | N28: AST | O28: Wild | S28: The Spindle | T28: 85 | U28: 103 | V28: cm | X28: g | Y28: 1 | Z28: 0 | AA28: 1 | AB28: UNK | AC28: 79 | AD28: 34 | AE28: 53 | AH28: Penobscot | AJ28: A69-2801-201240 | AK28: -68.817097 | AL28: 44.686268
A29: 2025-AST-0012 | B29: 45874 | C29: 3DD.003E185F7C | F29: A69-2801 | G29: 201242 | H29: 2560 | I29: 0 | N29: AST | O29: Wild | S29: The Spindle | T29: 90 | U29: 108 | V29: cm | X29: g | Y29: 1 | Z29: 0 | AA29: 1 | AB29: UNK | AC29: 71 | AD29: 36 | AE29: 55 | AH29: Penobscot | AI29: RIGHT PECTORAL WOUND | AJ29: A69-2801-201242 | AK29: -68.817097 | AL29: 44.686268
A30: 2025-AST-0011 | B30: 45874 | C30: 3DD.003E185F8A | F30: A69-2801 | G30: 201243 | H30: 2560 | I30: 0 | N30: AST | O30: Wild | S30: The Spindle | T30: 87 | U30: 101 | V30: cm | X30: g | Y30: 1 | Z30: 0 | AA30: 1 | AB30: UNK | AC30: 63 | AD30: 33 | AE30: 47 | AH30: Penobscot | AJ30: A69-2801-201243 | AK30: -68.817097 | AL30: 44.686268
A31: 2025-AST-0010 | B31: 45874 | C31: 3DD.003E185F8B | F31: A69-2801 | G31: 201246 | H31: 2560 | I31: 0 | N31: AST | O31: Wild | S31: The Spindle | T31: 94 | U31: 113 | V31: cm | X31: g | Y31: 1 | Z31: 0 | AA31: 1 | AB31: UNK | AC31: 77 | AD31: 37 | AE31: 51 | AH31: Penobscot | AJ31: A69-2801-201246 | AK31: -68.817097 | AL31: 44.686268
A32: SNS-2012-007 | B32: 45874 | C32: 3D9.1C2D6CC918 | F32: A69-2801 | G32: 201232 | H32: 2560 | I32: 0 | N32: SNS | O32: Wild | P32: FLOY: 101239; Genetic ID: G-889; Photo ID: 12-034; | Q32: Sturgeon-PNR | R32: Penobscot River | S32: The Spindle | T32: 89 | U32: 100 | V32: cm | X32: g | Y32: 1 | Z32: 1 | AA32: 0 | AB32: UNK | AC32: 67 | AD32: 38 | AE32: 59 | AH32: Penobscot | AJ32: A69-2801-201232 | AK32: -68.817097 | AL32: 44.686268
A33: SNS-2020-019 | B33: 45874 | C33: 3DD.003D99263F | F33: A69-2801 | G33: 201234 | H33: 2560 | I33: 0 | N33: SNS | O33: Wild | P33: Genetic ID: G-2039; | Q33: Sturgeon-PNR | R33: Penobscot River | S33: The Spindle | T33: 86 | U33: 101 | V33: cm | X33: g | Y33: 1 | Z33: 1 | AA33: 0 | AB33: UNK | AC33: 62 | AD33: 47 | AE33: 54 | AH33: Penobscot | AJ33: A69-2801-201234 | AK33: -68.817097 | AL33: 44.686268
A34: 2025-SNS-0014 | B34: 45874 | C34: 3DD.003E185F7B | F34: A69-2801 | G34: 201236 | H34: 2560 | I34: 0 | N34: SNS | O34: Wild | S34: The Spindle | T34: 87 | U34: 102 | V34: cm | X34: g | Y34: 1 | Z34: 0 | AA34: 1 | AB34: UNK | AC34: 67 | AD34: 47 | AE34: 53 | AH34: Penobscot | AJ34: A69-2801-201236 | AK34: -68.817097 | AL34: 44.686268
A35: 2025-SNS-0017 | B35: 45874 | C35: 3DD.003E185F66 | F35: A69-2801 | G35: 201239 | H35: 2560 | I35: 0 | N35: SNS | O35: Wild | S35: The Spindle | T35: 94 | U35: 108 | V35: cm | X35: g | Y35: 1 | Z35: 0 | AA35: 1 | AB35: UNK | AC35: 73 | AD35: 50 | AE35: 66 | AH35: Penobscot | AJ35: A69-2801-201239 | AK35: -68.817097 | AL35: 44.686268
A36: 2025-SNS-0015 | B36: 45874 | C36: 3DD.003E185F82 | F36: A69-2801 | G36: 201241 | H36: 2560 | I36: 0 | N36: SNS | O36: Wild | S36: The Spindle | T36: 95 | U36: 109 | V36: cm | X36: g | Y36: 1 | Z36: 0 | AA36: 1 | AB36: UNK | AC36: 71 | AD36: 49 | AE36: 61 | AH36: Penobscot | AJ36: A69-2801-201241 | AK36: -68.817097 | AL36: 44.686268
A37: SNS-2017-228 | B37: 45874 | C37: 3DD.003BEF3671 | F37: A69-2801 | G37: 201244 | H37: 2560 | I37: 0 | N37: SNS | O37: Wild | P37: FLOY: 53262; Genetic ID: G-1751; Photo ID: 19-039; | Q37: Sturgeon-PNR | R37: Penobscot River | S37: The Spindle | T37: 91 | U37: 105 | V37: cm | X37: g | Y37: 1 | Z37: 1 | AA37: 0 | AB37: UNK | AC37: 73 | AD37: 49 | AE37: 59 | AH37: Penobscot | AJ37: A69-2801-201244 | AK37: -68.817097 | AL37: 44.686268
A38: 2025-SNS-0016 | B38: 45874 | C38: 3DD.003E185F6E | F38: A69-2801 | G38: 201245 | H38: 2560 | I38: 0 | N38: SNS | O38: Wild | S38: The Spindle | T38: 109 | U38: 118 | V38: cm | X38: g | Y38: 1 | Z38: 0 | AA38: 1 | AB38: UNK | AC38: 69 | AD38: 48 | AE38: 66 | AH38: Penobscot | AJ38: A69-2801-201245 | AK38: -68.817097 | AL38: 44.686268
A39: SNS-2011-164 | B39: 45874 | C39: 3D9.1C2D7E000E | F39: A69-2801 | G39: 201247 | H39: 2560 | I39: 0 | N39: SNS | O39: Wild | P39: FLOY: 102374; Genetic ID: G-847; Photo ID: 15-162; | Q39: Sturgeon-PNR | R39: Penobscot River | S39: The Spindle | T39: 90 | U39: 104 | V39: cm | X39: g | Y39: 1 | Z39: 1 | AA39: 0 | AB39: UNK | AC39: 68 | AD39: 39 | AE39: 55 | AH39: Penobscot | AJ39: A69-2801-201247 | AK39: -68.817097 | AL39: 44.686268
A40: 2025-AST-0019 | B40: 45886 | C40: 3DD.003E185F58 | F40: A69-2801 | G40: 201226 | H40: 2560 | I40: 0 | N40: AST | O40: Wild | S40: The Spindle | T40: 95 | U40: 112 | V40: cm | X40: g | Y40: 1 | Z40: 0 | AA40: 1 | AB40: UNK | AC40: 75 | AD40: 34 | AE40: 56 | AH40: Penobscot | AJ40: A69-2801-201226 | AK40: -68.817097 | AL40: 44.686268
...

Sheet Sheet2
A1: PIT # | B1: CODE | D1: V16# | E1: Code | F1: Short | J1: Serial number | K1: full code
A2: 1 | B2: 3DD.003E185F8C | D2: 1 | E2: A69-2801-201127 | F2: =VALUE(RIGHT(E2,6)) -> 201127 | J2: 1638355 | K2: A69-2801-201127
A3: 2 | B3: 3DD.003E185F8D | D3: 2 | E3: A69-2801-201128 | F3: =VALUE(RIGHT(E3,6)) -> 201128 | J3: 1638356 | K3: A69-2801-201128
A4: 3 | B4: 3DD.003E185F93 | D4: 3 | E4: A69-2801-201129 | F4: =VALUE(RIGHT(E4,6)) -> 201129 | J4: 1638357 | K4: A69-2801-201129
A5: 4 | B5: 3DD.003E185F8F | D5: 4 | E5: A69-2801-201130 | F5: =VALUE(RIGHT(E5,6)) -> 201130 | J5: 1638358 | K5: A69-2801-201130
A6: 5 | B6: 3DD.003E185F7D | D6: 5 | E6: A69-2801-201131 | F6: =VALUE(RIGHT(E6,6)) -> 201131 | J6: 1638359 | K6: A69-2801-201131
A7: 6 | B7: 3DD.003E185F77 | D7: 6 | E7: A69-2801-201132 | F7: =VALUE(RIGHT(E7,6)) -> 201132 | J7: 1638360 | K7: A69-2801-201132
A8: 7 | B8: 3DD.003E185F76 | D8: 7 | E8: A69-2801-201133 | F8: =VALUE(RIGHT(E8,6)) -> 201133 | J8: 1638361 | K8: A69-2801-201133
A9: 8 | B9: 3DD.003E185F92 | D9: 8 | E9: A69-2801-201134 | F9: =VALUE(RIGHT(E9,6)) -> 201134 | J9: 1638362 | K9: A69-2801-201134
A10: 9 | B10: 3DD.003E185F95 | D10: 9 | E10: A69-2801-201212 | F10: =VALUE(RIGHT(E10,6)) -> 201212 | J10: 1645258 | K10: A69-2801-201212
A11: 10 | B11: 3DD.003E185F86 | D11: 10 | E11: A69-2801-201213 | F11: =VALUE(RIGHT(E11,6)) -> 201213 | J11: 1645259 | K11: A69-2801-201213
A12: 11 | B12: 3DD.003E185F7F | D12: 11 | E12: A69-2801-201214 | F12: =VALUE(RIGHT(E12,6)) -> 201214 | J12: 1645260 | K12: A69-2801-201214
A13: 12 | B13: 3DD.003E185F94 | D13: 12 | E13: A69-2801-201215 | F13: =VALUE(RIGHT(E13,6)) -> 201215 | J13: 1645261 | K13: A69-2801-201215
... A24: 23 | B24: 3DD.003E185F85 | D24: 23 | E24: A69-2801-201226 | F24: =VALUE(RIGHT(E24,6)) -> 201226 | J24: 1645272 | K24: A69-2801-201226
A25: 24 | B25: 3DD.003E185F68 | D25: 24 | E25: A69-2801-201227 | F25: =VALUE(RIGHT(E25,6)) -> 201227 | J25: 1645273 | K25: A69-2801-201227 | T25: 6
A26: 25 | B26: 3DD.003E185F69 | D26: 25 | E26: A69-2801-201228 | F26: =VALUE(RIGHT(E26,6)) -> 201228 | J26: 1645274 | K26: A69-2801-201228
A27: 26 | B27: 3DD.003E185F7B | D27: 26 | E27: A69-2801-201229 | F27: =VALUE(RIGHT(E27,6)) -> 201229 | J27: 1645275 | K27: A69-2801-201229
A28: 27 | B28: 3DD.003E185F82 | D28: 27 | E28: A69-2801-201230 | F28: =VALUE(RIGHT(E28,6)) -> 201230 | J28: 1645276 | K28: A69-2801-201230
A29: 28 | B29: 3DD.003E185F6E | D29: 28 | E29: A69-2801-201231 | F29: =VALUE(RIGHT(E29,6)) -> 201231 | J29: 1645277 | K29: A69-2801-201231
A30: 29 | B30: 3DD.003E185F8B | D30: 29 | E30: A69-2801-201232 | F30: =VALUE(RIGHT(E30,6)) -> 201232 | J30: 1645278 | K30: A69-2801-201232
A31: 30 | B31: 3DD.003E185F8A | D31: 30 | E31: A69-2801-201233 | F31: =VALUE(RIGHT(E31,6)) -> 201233 | J31: 1645279 | K31: A69-2801-201233
A32: 31 | B32: 3DD.003E185F7C | D32: 31 | E32: A69-2801-201234 | F32: =VALUE(RIGHT(E32,6)) -> 201234 | J32: 1645280 | K32: A69-2801-201234
A33: 32 | B33: 3DD.003E185F81 | D33: 32 | E33: A69-2801-201235 | F33: =VALUE(RIGHT(E33,6)) -> 201235 | J33: 1645281 | K33: A69-2801-201235
A34: 33 | B34: 3DD.003E185F6F | D34: 33 | E34: A69-2801-201236 | F34: =VALUE(RIGHT(E34,6)) -> 201236 | J34: 1645282 | K34: A69-2801-201236
A35: 34 | B35: 3DD.003E185F7A | D35: 34 | E35: A69-2801-201237 | F35: =VALUE(RIGHT(E35,6)) -> 201237 | J35: 1645283 | K35: A69-2801-201237
A36: 35 | B36: 3DD.003E185F66 | D36: 35 | E36: A69-2801-201238 | F36: =VALUE(RIGHT(E36,6)) -> 201238 | J36: 1645284 | K36: A69-2801-201238
A37: 36 | B37: 3DD.003E185F83 | D37: 36 | E37: A69-2801-201239 | F37: =VALUE(RIGHT(E37,6)) -> 201239 | J37: 1645285 | K37: A69-2801-201239
... A51: 50 | B51: 3DD.003E185F39 | D51: 50 | E51: A69-2801-201253 | F51: =VALUE(RIGHT(E51,6)) -> 201253 | J51: 1645299 | K51: A69-2801-201253
A52: 51 | B52: 3DD.003E185F57
A53: 52 | B53: 3DD.003E185F56
A54: 53 | B54: 3DD.003E185F79
A55: 54 | B55: 3DD.003E185F5D
A56: 55 | B56: 3DD.003E185F4E
A57: 56 | B57: 3DD.003E185F46
A58: 57 | B58: 3DD.003E185F4B
A59: 58 | B59: 3DD.003E185F80
A60: 59 | B60: 3DD.003E185F55
A61: 60 | B61: 3DD.003E185F44

Sheet Sheet1
A1: 11 | B1: 1221719 | C1: A69-9001 | D1: 21252
A2: 12 | B2: 1221720 | C2: A69-9001 | D2: 21253
A3: 15 | B3: 1221721 | C3: A69-9001 | D3: 21254
A4: 24 | B4: 1221722 | C4: A69-9001 | D4: 21255
A5: 13 | B5: 1221723 | C5: A69-9001 | D5: 21256
A6: 10 | B6: 1221724 | C6: A69-9001 | D6: 21257
A7: 21 | B7: 1221725 | C7: A69-9001 | D7: 21258
A8: 20 | B8: 1221726 | C8: A69-9001 | D8: 21259
A9: 19 | B9: 1221727 | C9: A69-9001 | D9: 21260
A10: 23 | B10: 1221728 | C10: A69-9001 | D10: 21261
A11: 17 | B11: 1221729 | C11: A69-9001 | D11: 21262
A12: 16 | B12: 1221730 | C12: A69-9001 | D12: 21263
... A39: 45 | B39: 1299385 | C39: A69-9001 | D39: 9165
